2024-11-08 09:02:50,838 - INFO - Starting parallel search operations...
2024-11-08 09:02:50,838 - INFO - Starting Google search and content collection...
2024-11-08 09:02:50,839 - INFO - Starting Archive vector search...
2024-11-08 09:02:50,839 - INFO - Waiting for both search operations to complete...
2024-11-08 09:02:52,372 - INFO - Successfully completed Google search and content collection
2024-11-08 09:02:52,372 - INFO - Google search and content collection output:
Search query loaded from topic.txt: Moment of Inertia tensor
Error: HTTPSConnectionPool(host='www.googleapis.com', port=443): Max retries exceeded with url: /customsearch/v1?key=AIzaSyDTUZdD1RhA9oey878fzA5o3REMnymR9hk&cx=33f4586468b0c41e6&q=Moment+of+Inertia+tensor&num=10 (Caused by NewConnectionError('<urllib3.connection.HTTPSConnection object at 0x000002AFABB55910>: Failed to establish a new connection: [Errno 11001] getaddrinfo failed'))

2024-11-08 09:03:04,819 - ERROR - Error in Archive vector search:
Traceback (most recent call last):
  File "C:\Users\Lenovo\AppData\Local\Packages\PythonSoftwareFoundation.Python.3.9_qbz5n2kfra8p0\LocalCache\local-packages\Python39\site-packages\httpcore\_exceptions.py", line 10, in map_exceptions
    yield
  File "C:\Users\Lenovo\AppData\Local\Packages\PythonSoftwareFoundation.Python.3.9_qbz5n2kfra8p0\LocalCache\local-packages\Python39\site-packages\httpcore\_backends\sync.py", line 206, in connect_tcp
    sock = socket.create_connection(
  File "C:\Program Files\WindowsApps\PythonSoftwareFoundation.Python.3.9_3.9.3568.0_x64__qbz5n2kfra8p0\lib\socket.py", line 823, in create_connection
    for res in getaddrinfo(host, port, 0, SOCK_STREAM):
  File "C:\Program Files\WindowsApps\PythonSoftwareFoundation.Python.3.9_3.9.3568.0_x64__qbz5n2kfra8p0\lib\socket.py", line 954, in getaddrinfo
    for res in _socket.getaddrinfo(host, port, family, type, proto, flags):
socket.gaierror: [Errno 11001] getaddrinfo failed

The above exception was the direct cause of the following exception:

Traceback (most recent call last):
  File "C:\Users\Lenovo\AppData\Local\Packages\PythonSoftwareFoundation.Python.3.9_qbz5n2kfra8p0\LocalCache\local-packages\Python39\site-packages\httpx\_transports\default.py", line 67, in map_httpcore_exceptions
    yield
  File "C:\Users\Lenovo\AppData\Local\Packages\PythonSoftwareFoundation.Python.3.9_qbz5n2kfra8p0\LocalCache\local-packages\Python39\site-packages\httpx\_transports\default.py", line 231, in handle_request
    resp = self._pool.handle_request(req)
  File "C:\Users\Lenovo\AppData\Local\Packages\PythonSoftwareFoundation.Python.3.9_qbz5n2kfra8p0\LocalCache\local-packages\Python39\site-packages\httpcore\_sync\connection_pool.py", line 268, in handle_request
    raise exc
  File "C:\Users\Lenovo\AppData\Local\Packages\PythonSoftwareFoundation.Python.3.9_qbz5n2kfra8p0\LocalCache\local-packages\Python39\site-packages\httpcore\_sync\connection_pool.py", line 251, in handle_request
    response = connection.handle_request(request)
  File "C:\Users\Lenovo\AppData\Local\Packages\PythonSoftwareFoundation.Python.3.9_qbz5n2kfra8p0\LocalCache\local-packages\Python39\site-packages\httpcore\_sync\connection.py", line 99, in handle_request
    raise exc
  File "C:\Users\Lenovo\AppData\Local\Packages\PythonSoftwareFoundation.Python.3.9_qbz5n2kfra8p0\LocalCache\local-packages\Python39\site-packages\httpcore\_sync\connection.py", line 76, in handle_request
    stream = self._connect(request)
  File "C:\Users\Lenovo\AppData\Local\Packages\PythonSoftwareFoundation.Python.3.9_qbz5n2kfra8p0\LocalCache\local-packages\Python39\site-packages\httpcore\_sync\connection.py", line 124, in _connect
    stream = self._network_backend.connect_tcp(**kwargs)
  File "C:\Users\Lenovo\AppData\Local\Packages\PythonSoftwareFoundation.Python.3.9_qbz5n2kfra8p0\LocalCache\local-packages\Python39\site-packages\httpcore\_backends\sync.py", line 213, in connect_tcp
    sock.setsockopt(socket.IPPROTO_TCP, socket.TCP_NODELAY, 1)
  File "C:\Program Files\WindowsApps\PythonSoftwareFoundation.Python.3.9_3.9.3568.0_x64__qbz5n2kfra8p0\lib\contextlib.py", line 137, in __exit__
    self.gen.throw(typ, value, traceback)
  File "C:\Users\Lenovo\AppData\Local\Packages\PythonSoftwareFoundation.Python.3.9_qbz5n2kfra8p0\LocalCache\local-packages\Python39\site-packages\httpcore\_exceptions.py", line 14, in map_exceptions
    raise to_exc(exc) from exc
httpcore.ConnectError: [Errno 11001] getaddrinfo failed

The above exception was the direct cause of the following exception:

Traceback (most recent call last):
  File "C:\Users\Lenovo\AppData\Local\Packages\PythonSoftwareFoundation.Python.3.9_qbz5n2kfra8p0\LocalCache\local-packages\Python39\site-packages\openai\_base_client.py", line 990, in _request
    response = self._client.send(
  File "C:\Users\Lenovo\AppData\Local\Packages\PythonSoftwareFoundation.Python.3.9_qbz5n2kfra8p0\LocalCache\local-packages\Python39\site-packages\httpx\_client.py", line 915, in send
    response = self._send_handling_auth(
  File "C:\Users\Lenovo\AppData\Local\Packages\PythonSoftwareFoundation.Python.3.9_qbz5n2kfra8p0\LocalCache\local-packages\Python39\site-packages\httpx\_client.py", line 943, in _send_handling_auth
    response = self._send_handling_redirects(
  File "C:\Users\Lenovo\AppData\Local\Packages\PythonSoftwareFoundation.Python.3.9_qbz5n2kfra8p0\LocalCache\local-packages\Python39\site-packages\httpx\_client.py", line 980, in _send_handling_redirects
    response = self._send_single_request(request)
  File "C:\Users\Lenovo\AppData\Local\Packages\PythonSoftwareFoundation.Python.3.9_qbz5n2kfra8p0\LocalCache\local-packages\Python39\site-packages\httpx\_client.py", line 1016, in _send_single_request
    response = transport.handle_request(request)
  File "C:\Users\Lenovo\AppData\Local\Packages\PythonSoftwareFoundation.Python.3.9_qbz5n2kfra8p0\LocalCache\local-packages\Python39\site-packages\httpx\_transports\default.py", line 231, in handle_request
    resp = self._pool.handle_request(req)
  File "C:\Program Files\WindowsApps\PythonSoftwareFoundation.Python.3.9_3.9.3568.0_x64__qbz5n2kfra8p0\lib\contextlib.py", line 137, in __exit__
    self.gen.throw(typ, value, traceback)
  File "C:\Users\Lenovo\AppData\Local\Packages\PythonSoftwareFoundation.Python.3.9_qbz5n2kfra8p0\LocalCache\local-packages\Python39\site-packages\httpx\_transports\default.py", line 84, in map_httpcore_exceptions
    raise mapped_exc(message) from exc
httpx.ConnectError: [Errno 11001] getaddrinfo failed

During handling of the above exception, another exception occurred:

Traceback (most recent call last):
  File "C:\Users\Lenovo\AppData\Local\Packages\PythonSoftwareFoundation.Python.3.9_qbz5n2kfra8p0\LocalCache\local-packages\Python39\site-packages\httpcore\_exceptions.py", line 10, in map_exceptions
    yield
  File "C:\Users\Lenovo\AppData\Local\Packages\PythonSoftwareFoundation.Python.3.9_qbz5n2kfra8p0\LocalCache\local-packages\Python39\site-packages\httpcore\_backends\sync.py", line 206, in connect_tcp
    sock = socket.create_connection(
  File "C:\Program Files\WindowsApps\PythonSoftwareFoundation.Python.3.9_3.9.3568.0_x64__qbz5n2kfra8p0\lib\socket.py", line 823, in create_connection
    for res in getaddrinfo(host, port, 0, SOCK_STREAM):
  File "C:\Program Files\WindowsApps\PythonSoftwareFoundation.Python.3.9_3.9.3568.0_x64__qbz5n2kfra8p0\lib\socket.py", line 954, in getaddrinfo
    for res in _socket.getaddrinfo(host, port, family, type, proto, flags):
socket.gaierror: [Errno 11001] getaddrinfo failed

The above exception was the direct cause of the following exception:

Traceback (most recent call last):
  File "C:\Users\Lenovo\AppData\Local\Packages\PythonSoftwareFoundation.Python.3.9_qbz5n2kfra8p0\LocalCache\local-packages\Python39\site-packages\httpx\_transports\default.py", line 67, in map_httpcore_exceptions
    yield
  File "C:\Users\Lenovo\AppData\Local\Packages\PythonSoftwareFoundation.Python.3.9_qbz5n2kfra8p0\LocalCache\local-packages\Python39\site-packages\httpx\_transports\default.py", line 231, in handle_request
    resp = self._pool.handle_request(req)
  File "C:\Users\Lenovo\AppData\Local\Packages\PythonSoftwareFoundation.Python.3.9_qbz5n2kfra8p0\LocalCache\local-packages\Python39\site-packages\httpcore\_sync\connection_pool.py", line 268, in handle_request
    raise exc
  File "C:\Users\Lenovo\AppData\Local\Packages\PythonSoftwareFoundation.Python.3.9_qbz5n2kfra8p0\LocalCache\local-packages\Python39\site-packages\httpcore\_sync\connection_pool.py", line 251, in handle_request
    response = connection.handle_request(request)
  File "C:\Users\Lenovo\AppData\Local\Packages\PythonSoftwareFoundation.Python.3.9_qbz5n2kfra8p0\LocalCache\local-packages\Python39\site-packages\httpcore\_sync\connection.py", line 99, in handle_request
    raise exc
  File "C:\Users\Lenovo\AppData\Local\Packages\PythonSoftwareFoundation.Python.3.9_qbz5n2kfra8p0\LocalCache\local-packages\Python39\site-packages\httpcore\_sync\connection.py", line 76, in handle_request
    stream = self._connect(request)
  File "C:\Users\Lenovo\AppData\Local\Packages\PythonSoftwareFoundation.Python.3.9_qbz5n2kfra8p0\LocalCache\local-packages\Python39\site-packages\httpcore\_sync\connection.py", line 124, in _connect
    stream = self._network_backend.connect_tcp(**kwargs)
  File "C:\Users\Lenovo\AppData\Local\Packages\PythonSoftwareFoundation.Python.3.9_qbz5n2kfra8p0\LocalCache\local-packages\Python39\site-packages\httpcore\_backends\sync.py", line 213, in connect_tcp
    sock.setsockopt(socket.IPPROTO_TCP, socket.TCP_NODELAY, 1)
  File "C:\Program Files\WindowsApps\PythonSoftwareFoundation.Python.3.9_3.9.3568.0_x64__qbz5n2kfra8p0\lib\contextlib.py", line 137, in __exit__
    self.gen.throw(typ, value, traceback)
  File "C:\Users\Lenovo\AppData\Local\Packages\PythonSoftwareFoundation.Python.3.9_qbz5n2kfra8p0\LocalCache\local-packages\Python39\site-packages\httpcore\_exceptions.py", line 14, in map_exceptions
    raise to_exc(exc) from exc
httpcore.ConnectError: [Errno 11001] getaddrinfo failed

The above exception was the direct cause of the following exception:

Traceback (most recent call last):
  File "C:\Users\Lenovo\AppData\Local\Packages\PythonSoftwareFoundation.Python.3.9_qbz5n2kfra8p0\LocalCache\local-packages\Python39\site-packages\openai\_base_client.py", line 990, in _request
    response = self._client.send(
  File "C:\Users\Lenovo\AppData\Local\Packages\PythonSoftwareFoundation.Python.3.9_qbz5n2kfra8p0\LocalCache\local-packages\Python39\site-packages\httpx\_client.py", line 915, in send
    response = self._send_handling_auth(
  File "C:\Users\Lenovo\AppData\Local\Packages\PythonSoftwareFoundation.Python.3.9_qbz5n2kfra8p0\LocalCache\local-packages\Python39\site-packages\httpx\_client.py", line 943, in _send_handling_auth
    response = self._send_handling_redirects(
  File "C:\Users\Lenovo\AppData\Local\Packages\PythonSoftwareFoundation.Python.3.9_qbz5n2kfra8p0\LocalCache\local-packages\Python39\site-packages\httpx\_client.py", line 980, in _send_handling_redirects
    response = self._send_single_request(request)
  File "C:\Users\Lenovo\AppData\Local\Packages\PythonSoftwareFoundation.Python.3.9_qbz5n2kfra8p0\LocalCache\local-packages\Python39\site-packages\httpx\_client.py", line 1016, in _send_single_request
    response = transport.handle_request(request)
  File "C:\Users\Lenovo\AppData\Local\Packages\PythonSoftwareFoundation.Python.3.9_qbz5n2kfra8p0\LocalCache\local-packages\Python39\site-packages\httpx\_transports\default.py", line 231, in handle_request
    resp = self._pool.handle_request(req)
  File "C:\Program Files\WindowsApps\PythonSoftwareFoundation.Python.3.9_3.9.3568.0_x64__qbz5n2kfra8p0\lib\contextlib.py", line 137, in __exit__
    self.gen.throw(typ, value, traceback)
  File "C:\Users\Lenovo\AppData\Local\Packages\PythonSoftwareFoundation.Python.3.9_qbz5n2kfra8p0\LocalCache\local-packages\Python39\site-packages\httpx\_transports\default.py", line 84, in map_httpcore_exceptions
    raise mapped_exc(message) from exc
httpx.ConnectError: [Errno 11001] getaddrinfo failed

During handling of the above exception, another exception occurred:

Traceback (most recent call last):
  File "C:\Users\Lenovo\AppData\Local\Packages\PythonSoftwareFoundation.Python.3.9_qbz5n2kfra8p0\LocalCache\local-packages\Python39\site-packages\httpcore\_exceptions.py", line 10, in map_exceptions
    yield
  File "C:\Users\Lenovo\AppData\Local\Packages\PythonSoftwareFoundation.Python.3.9_qbz5n2kfra8p0\LocalCache\local-packages\Python39\site-packages\httpcore\_backends\sync.py", line 206, in connect_tcp
    sock = socket.create_connection(
  File "C:\Program Files\WindowsApps\PythonSoftwareFoundation.Python.3.9_3.9.3568.0_x64__qbz5n2kfra8p0\lib\socket.py", line 823, in create_connection
    for res in getaddrinfo(host, port, 0, SOCK_STREAM):
  File "C:\Program Files\WindowsApps\PythonSoftwareFoundation.Python.3.9_3.9.3568.0_x64__qbz5n2kfra8p0\lib\socket.py", line 954, in getaddrinfo
    for res in _socket.getaddrinfo(host, port, family, type, proto, flags):
socket.gaierror: [Errno 11001] getaddrinfo failed

The above exception was the direct cause of the following exception:

Traceback (most recent call last):
  File "C:\Users\Lenovo\AppData\Local\Packages\PythonSoftwareFoundation.Python.3.9_qbz5n2kfra8p0\LocalCache\local-packages\Python39\site-packages\httpx\_transports\default.py", line 67, in map_httpcore_exceptions
    yield
  File "C:\Users\Lenovo\AppData\Local\Packages\PythonSoftwareFoundation.Python.3.9_qbz5n2kfra8p0\LocalCache\local-packages\Python39\site-packages\httpx\_transports\default.py", line 231, in handle_request
    resp = self._pool.handle_request(req)
  File "C:\Users\Lenovo\AppData\Local\Packages\PythonSoftwareFoundation.Python.3.9_qbz5n2kfra8p0\LocalCache\local-packages\Python39\site-packages\httpcore\_sync\connection_pool.py", line 268, in handle_request
    raise exc
  File "C:\Users\Lenovo\AppData\Local\Packages\PythonSoftwareFoundation.Python.3.9_qbz5n2kfra8p0\LocalCache\local-packages\Python39\site-packages\httpcore\_sync\connection_pool.py", line 251, in handle_request
    response = connection.handle_request(request)
  File "C:\Users\Lenovo\AppData\Local\Packages\PythonSoftwareFoundation.Python.3.9_qbz5n2kfra8p0\LocalCache\local-packages\Python39\site-packages\httpcore\_sync\connection.py", line 99, in handle_request
    raise exc
  File "C:\Users\Lenovo\AppData\Local\Packages\PythonSoftwareFoundation.Python.3.9_qbz5n2kfra8p0\LocalCache\local-packages\Python39\site-packages\httpcore\_sync\connection.py", line 76, in handle_request
    stream = self._connect(request)
  File "C:\Users\Lenovo\AppData\Local\Packages\PythonSoftwareFoundation.Python.3.9_qbz5n2kfra8p0\LocalCache\local-packages\Python39\site-packages\httpcore\_sync\connection.py", line 124, in _connect
    stream = self._network_backend.connect_tcp(**kwargs)
  File "C:\Users\Lenovo\AppData\Local\Packages\PythonSoftwareFoundation.Python.3.9_qbz5n2kfra8p0\LocalCache\local-packages\Python39\site-packages\httpcore\_backends\sync.py", line 213, in connect_tcp
    sock.setsockopt(socket.IPPROTO_TCP, socket.TCP_NODELAY, 1)
  File "C:\Program Files\WindowsApps\PythonSoftwareFoundation.Python.3.9_3.9.3568.0_x64__qbz5n2kfra8p0\lib\contextlib.py", line 137, in __exit__
    self.gen.throw(typ, value, traceback)
  File "C:\Users\Lenovo\AppData\Local\Packages\PythonSoftwareFoundation.Python.3.9_qbz5n2kfra8p0\LocalCache\local-packages\Python39\site-packages\httpcore\_exceptions.py", line 14, in map_exceptions
    raise to_exc(exc) from exc
httpcore.ConnectError: [Errno 11001] getaddrinfo failed

The above exception was the direct cause of the following exception:

Traceback (most recent call last):
  File "C:\Users\Lenovo\AppData\Local\Packages\PythonSoftwareFoundation.Python.3.9_qbz5n2kfra8p0\LocalCache\local-packages\Python39\site-packages\openai\_base_client.py", line 990, in _request
    response = self._client.send(
  File "C:\Users\Lenovo\AppData\Local\Packages\PythonSoftwareFoundation.Python.3.9_qbz5n2kfra8p0\LocalCache\local-packages\Python39\site-packages\httpx\_client.py", line 915, in send
    response = self._send_handling_auth(
  File "C:\Users\Lenovo\AppData\Local\Packages\PythonSoftwareFoundation.Python.3.9_qbz5n2kfra8p0\LocalCache\local-packages\Python39\site-packages\httpx\_client.py", line 943, in _send_handling_auth
    response = self._send_handling_redirects(
  File "C:\Users\Lenovo\AppData\Local\Packages\PythonSoftwareFoundation.Python.3.9_qbz5n2kfra8p0\LocalCache\local-packages\Python39\site-packages\httpx\_client.py", line 980, in _send_handling_redirects
    response = self._send_single_request(request)
  File "C:\Users\Lenovo\AppData\Local\Packages\PythonSoftwareFoundation.Python.3.9_qbz5n2kfra8p0\LocalCache\local-packages\Python39\site-packages\httpx\_client.py", line 1016, in _send_single_request
    response = transport.handle_request(request)
  File "C:\Users\Lenovo\AppData\Local\Packages\PythonSoftwareFoundation.Python.3.9_qbz5n2kfra8p0\LocalCache\local-packages\Python39\site-packages\httpx\_transports\default.py", line 231, in handle_request
    resp = self._pool.handle_request(req)
  File "C:\Program Files\WindowsApps\PythonSoftwareFoundation.Python.3.9_3.9.3568.0_x64__qbz5n2kfra8p0\lib\contextlib.py", line 137, in __exit__
    self.gen.throw(typ, value, traceback)
  File "C:\Users\Lenovo\AppData\Local\Packages\PythonSoftwareFoundation.Python.3.9_qbz5n2kfra8p0\LocalCache\local-packages\Python39\site-packages\httpx\_transports\default.py", line 84, in map_httpcore_exceptions
    raise mapped_exc(message) from exc
httpx.ConnectError: [Errno 11001] getaddrinfo failed

The above exception was the direct cause of the following exception:

Traceback (most recent call last):
  File "F:\main\backend\vector_search.py", line 158, in <module>
    main()
  File "F:\main\backend\vector_search.py", line 152, in main
    results_by_book = search_all_books(query, book_data)
  File "F:\main\backend\vector_search.py", line 43, in search_all_books
    query_response = client.embeddings.create(
  File "C:\Users\Lenovo\AppData\Local\Packages\PythonSoftwareFoundation.Python.3.9_qbz5n2kfra8p0\LocalCache\local-packages\Python39\site-packages\openai\resources\embeddings.py", line 124, in create
    return self._post(
  File "C:\Users\Lenovo\AppData\Local\Packages\PythonSoftwareFoundation.Python.3.9_qbz5n2kfra8p0\LocalCache\local-packages\Python39\site-packages\openai\_base_client.py", line 1277, in post
    return cast(ResponseT, self.request(cast_to, opts, stream=stream, stream_cls=stream_cls))
  File "C:\Users\Lenovo\AppData\Local\Packages\PythonSoftwareFoundation.Python.3.9_qbz5n2kfra8p0\LocalCache\local-packages\Python39\site-packages\openai\_base_client.py", line 954, in request
    return self._request(
  File "C:\Users\Lenovo\AppData\Local\Packages\PythonSoftwareFoundation.Python.3.9_qbz5n2kfra8p0\LocalCache\local-packages\Python39\site-packages\openai\_base_client.py", line 1014, in _request
    return self._retry_request(
  File "C:\Users\Lenovo\AppData\Local\Packages\PythonSoftwareFoundation.Python.3.9_qbz5n2kfra8p0\LocalCache\local-packages\Python39\site-packages\openai\_base_client.py", line 1092, in _retry_request
    return self._request(
  File "C:\Users\Lenovo\AppData\Local\Packages\PythonSoftwareFoundation.Python.3.9_qbz5n2kfra8p0\LocalCache\local-packages\Python39\site-packages\openai\_base_client.py", line 1014, in _request
    return self._retry_request(
  File "C:\Users\Lenovo\AppData\Local\Packages\PythonSoftwareFoundation.Python.3.9_qbz5n2kfra8p0\LocalCache\local-packages\Python39\site-packages\openai\_base_client.py", line 1092, in _retry_request
    return self._request(
  File "C:\Users\Lenovo\AppData\Local\Packages\PythonSoftwareFoundation.Python.3.9_qbz5n2kfra8p0\LocalCache\local-packages\Python39\site-packages\openai\_base_client.py", line 1024, in _request
    raise APIConnectionError(request=request) from err
openai.APIConnectionError: Connection error.

2024-11-08 09:03:04,820 - ERROR - Error during parallel search execution: Command '['C:\\Users\\Lenovo\\AppData\\Local\\Microsoft\\WindowsApps\\PythonSoftwareFoundation.Python.3.9_qbz5n2kfra8p0\\python.exe', 'vector_search.py']' returned non-zero exit status 1.
2024-11-08 09:03:04,820 - ERROR - Article generation failed: Parallel search operations failed
